Traceback (most recent call last):
  File "C:\Users\Marietta\AppData\Local\Programs\Python\Python311\Lib\site-packages\urllib3\connection.py", line 196, in _new_conn
    sock = connection.create_connection(
           ^^^^^^^^^^^^^^^^^^^^^^^^^^^^^
  File "C:\Users\Marietta\AppData\Local\Programs\Python\Python311\Lib\site-packages\urllib3\util\connection.py", line 85, in create_connection
    raise err
  File "C:\Users\Marietta\AppData\Local\Programs\Python\Python311\Lib\site-packages\urllib3\util\connection.py", line 73, in create_connection
    sock.connect(sa)
TimeoutError: [WinError 10060] A connection attempt failed because the connected party did not properly respond after a period of time, or established connection failed because connected host has failed to respond

The above exception was the direct cause of the following exception:

Traceback (most recent call last):
  File "C:\Users\Marietta\AppData\Local\Programs\Python\Python311\Lib\site-packages\urllib3\connectionpool.py", line 789, in urlopen
    response = self._make_request(
               ^^^^^^^^^^^^^^^^^^^
  File "C:\Users\Marietta\AppData\Local\Programs\Python\Python311\Lib\site-packages\urllib3\connectionpool.py", line 490, in _make_request
    raise new_e
  File "C:\Users\Marietta\AppData\Local\Programs\Python\Python311\Lib\site-packages\urllib3\connectionpool.py", line 466, in _make_request
    self._validate_conn(conn)
  File "C:\Users\Marietta\AppData\Local\Programs\Python\Python311\Lib\site-packages\urllib3\connectionpool.py", line 1095, in _validate_conn
    conn.connect()
  File "C:\Users\Marietta\AppData\Local\Programs\Python\Python311\Lib\site-packages\urllib3\connection.py", line 615, in connect
    self.sock = sock = self._new_conn()
                       ^^^^^^^^^^^^^^^^
  File "C:\Users\Marietta\AppData\Local\Programs\Python\Python311\Lib\site-packages\urllib3\connection.py", line 205, in _new_conn
    raise ConnectTimeoutError(
urllib3.exceptions.ConnectTimeoutError: (<urllib3.connection.HTTPSConnection object at 0x00000226D7A00C50>, 'Connection to api.openai.com timed out. (connect timeout=600)')

The above exception was the direct cause of the following exception:

Traceback (most recent call last):
  File "C:\Users\Marietta\AppData\Local\Programs\Python\Python311\Lib\site-packages\requests\adapters.py", line 667, in send
    resp = conn.urlopen(
           ^^^^^^^^^^^^^
  File "C:\Users\Marietta\AppData\Local\Programs\Python\Python311\Lib\site-packages\urllib3\connectionpool.py", line 873, in urlopen
    return self.urlopen(
           ^^^^^^^^^^^^^
  File "C:\Users\Marietta\AppData\Local\Programs\Python\Python311\Lib\site-packages\urllib3\connectionpool.py", line 873, in urlopen
    return self.urlopen(
           ^^^^^^^^^^^^^
  File "C:\Users\Marietta\AppData\Local\Programs\Python\Python311\Lib\site-packages\urllib3\connectionpool.py", line 843, in urlopen
    retries = retries.increment(
              ^^^^^^^^^^^^^^^^^^
  File "C:\Users\Marietta\AppData\Local\Programs\Python\Python311\Lib\site-packages\urllib3\util\retry.py", line 519, in increment
    raise MaxRetryError(_pool, url, reason) from reason  # type: ignore[arg-type]
    ^^^^^^^^^^^^^^^^^^^^^^^^^^^^^^^^^^^^^^^^^^^^^^^^^^^
urllib3.exceptions.MaxRetryError: HTTPSConnectionPool(host='api.openai.com', port=443): Max retries exceeded with url: /v1/chat/completions (Caused by ConnectTimeoutError(<urllib3.connection.HTTPSConnection object at 0x00000226D7A00C50>, 'Connection to api.openai.com timed out. (connect timeout=600)'))

During handling of the above exception, another exception occurred:

Traceback (most recent call last):
  File "C:\Users\Marietta\AppData\Local\Programs\Python\Python311\Lib\site-packages\openai\api_requestor.py", line 596, in request_raw
    result = _thread_context.session.request(
             ^^^^^^^^^^^^^^^^^^^^^^^^^^^^^^^^
  File "C:\Users\Marietta\AppData\Local\Programs\Python\Python311\Lib\site-packages\requests\sessions.py", line 589, in request
    resp = self.send(prep, **send_kwargs)
           ^^^^^^^^^^^^^^^^^^^^^^^^^^^^^^
  File "C:\Users\Marietta\AppData\Local\Programs\Python\Python311\Lib\site-packages\requests\sessions.py", line 703, in send
    r = adapter.send(request, **kwargs)
        ^^^^^^^^^^^^^^^^^^^^^^^^^^^^^^^
  File "C:\Users\Marietta\AppData\Local\Programs\Python\Python311\Lib\site-packages\requests\adapters.py", line 688, in send
    raise ConnectTimeout(e, request=request)
requests.exceptions.ConnectTimeout: HTTPSConnectionPool(host='api.openai.com', port=443): Max retries exceeded with url: /v1/chat/completions (Caused by ConnectTimeoutError(<urllib3.connection.HTTPSConnection object at 0x00000226D7A00C50>, 'Connection to api.openai.com timed out. (connect timeout=600)'))

The above exception was the direct cause of the following exception:

Traceback (most recent call last):
  File "c:\Users\Marietta\Downloads\rapidamic\fromscratch\pdfeval.py", line 83, in <module>
    evaluation_response = evaluate_text_with_llm(text)
                          ^^^^^^^^^^^^^^^^^^^^^^^^^^^^
  File "c:\Users\Marietta\Downloads\rapidamic\fromscratch\pdfeval.py", line 66, in evaluate_text_with_llm
    response = openai.ChatCompletion.create(
               ^^^^^^^^^^^^^^^^^^^^^^^^^^^^^
  File "C:\Users\Marietta\AppData\Local\Programs\Python\Python311\Lib\site-packages\openai\api_resources\chat_completion.py", line 25, in create
    return super().create(*args, **kwargs)
           ^^^^^^^^^^^^^^^^^^^^^^^^^^^^^^^
  File "C:\Users\Marietta\AppData\Local\Programs\Python\Python311\Lib\site-packages\openai\api_resources\abstract\engine_api_resource.py", line 153, in create
    response, _, api_key = requestor.request(
                           ^^^^^^^^^^^^^^^^^^
  File "C:\Users\Marietta\AppData\Local\Programs\Python\Python311\Lib\site-packages\openai\api_requestor.py", line 288, in request
    result = self.request_raw(
             ^^^^^^^^^^^^^^^^^
  File "C:\Users\Marietta\AppData\Local\Programs\Python\Python311\Lib\site-packages\openai\api_requestor.py", line 607, in request_raw
    raise error.Timeout("Request timed out: {}".format(e)) from e
openai.error.Timeout: Request timed out: HTTPSConnectionPool(host='api.openai.com', port=443): Max retries exceeded with url: /v1/chat/completions (Caused by ConnectTimeoutError(<urllib3.connection.HTTPSConnection object at 0x00000226D7A00C50>, 'Connection to api.openai.com timed out. (connect timeout=600)'))

[Done] exited with code=1 in 127.468 seconds

